2023-05-05 19:26:59,439 - INFO - Logger set up with log level: 20(info)
2023-05-05 19:26:59,455 - INFO - Log file: logs\langflow.log
2023-05-05 19:27:16,811 - ERROR - File  is not accepted
Traceback (most recent call last):
  File "C:\Users\ABDUL REHMAN\AppData\Local\Programs\Python\Python310\lib\site-packages\langflow\api\validate.py", line 44, in post_validate_node
    graph = build_graph(data)
  File "C:\Users\ABDUL REHMAN\AppData\Local\Programs\Python\Python310\lib\site-packages\langflow\interface\run.py", line 49, in build_graph
    return Graph(nodes, edges)
  File "C:\Users\ABDUL REHMAN\AppData\Local\Programs\Python\Python310\lib\site-packages\langflow\graph\graph.py", line 43, in __init__
    self._build_graph()
  File "C:\Users\ABDUL REHMAN\AppData\Local\Programs\Python\Python310\lib\site-packages\langflow\graph\graph.py", line 56, in _build_graph
    node._build_params()
  File "C:\Users\ABDUL REHMAN\AppData\Local\Programs\Python\Python310\lib\site-packages\langflow\graph\base.py", line 94, in _build_params
    file_path = cache_utils.save_binary_file(
  File "C:\Users\ABDUL REHMAN\AppData\Local\Programs\Python\Python310\lib\site-packages\langflow\cache\base.py", line 25, in wrapper
    return func(*args, **kwargs)
  File "C:\Users\ABDUL REHMAN\AppData\Local\Programs\Python\Python310\lib\site-packages\langflow\cache\base.py", line 118, in save_binary_file
    raise ValueError(f"File {file_name} is not accepted")
ValueError: File  is not accepted
2023-05-05 19:27:16,811 - ERROR - File  is not accepted
Traceback (most recent call last):
  File "C:\Users\ABDUL REHMAN\AppData\Local\Programs\Python\Python310\lib\site-packages\langflow\api\validate.py", line 44, in post_validate_node
    graph = build_graph(data)
  File "C:\Users\ABDUL REHMAN\AppData\Local\Programs\Python\Python310\lib\site-packages\langflow\interface\run.py", line 49, in build_graph
    return Graph(nodes, edges)
  File "C:\Users\ABDUL REHMAN\AppData\Local\Programs\Python\Python310\lib\site-packages\langflow\graph\graph.py", line 43, in __init__
    self._build_graph()
  File "C:\Users\ABDUL REHMAN\AppData\Local\Programs\Python\Python310\lib\site-packages\langflow\graph\graph.py", line 56, in _build_graph
    node._build_params()
  File "C:\Users\ABDUL REHMAN\AppData\Local\Programs\Python\Python310\lib\site-packages\langflow\graph\base.py", line 94, in _build_params
    file_path = cache_utils.save_binary_file(
  File "C:\Users\ABDUL REHMAN\AppData\Local\Programs\Python\Python310\lib\site-packages\langflow\cache\base.py", line 25, in wrapper
    return func(*args, **kwargs)
  File "C:\Users\ABDUL REHMAN\AppData\Local\Programs\Python\Python310\lib\site-packages\langflow\cache\base.py", line 118, in save_binary_file
    raise ValueError(f"File {file_name} is not accepted")
ValueError: File  is not accepted
2023-05-05 19:27:16,821 - ERROR - File  is not accepted
Traceback (most recent call last):
  File "C:\Users\ABDUL REHMAN\AppData\Local\Programs\Python\Python310\lib\site-packages\langflow\api\validate.py", line 44, in post_validate_node
    graph = build_graph(data)
  File "C:\Users\ABDUL REHMAN\AppData\Local\Programs\Python\Python310\lib\site-packages\langflow\interface\run.py", line 49, in build_graph
    return Graph(nodes, edges)
  File "C:\Users\ABDUL REHMAN\AppData\Local\Programs\Python\Python310\lib\site-packages\langflow\graph\graph.py", line 43, in __init__
    self._build_graph()
  File "C:\Users\ABDUL REHMAN\AppData\Local\Programs\Python\Python310\lib\site-packages\langflow\graph\graph.py", line 56, in _build_graph
    node._build_params()
  File "C:\Users\ABDUL REHMAN\AppData\Local\Programs\Python\Python310\lib\site-packages\langflow\graph\base.py", line 94, in _build_params
    file_path = cache_utils.save_binary_file(
  File "C:\Users\ABDUL REHMAN\AppData\Local\Programs\Python\Python310\lib\site-packages\langflow\cache\base.py", line 25, in wrapper
    return func(*args, **kwargs)
  File "C:\Users\ABDUL REHMAN\AppData\Local\Programs\Python\Python310\lib\site-packages\langflow\cache\base.py", line 118, in save_binary_file
    raise ValueError(f"File {file_name} is not accepted")
ValueError: File  is not accepted
2023-05-05 19:27:16,832 - ERROR - File  is not accepted
Traceback (most recent call last):
  File "C:\Users\ABDUL REHMAN\AppData\Local\Programs\Python\Python310\lib\site-packages\langflow\api\validate.py", line 44, in post_validate_node
    graph = build_graph(data)
  File "C:\Users\ABDUL REHMAN\AppData\Local\Programs\Python\Python310\lib\site-packages\langflow\interface\run.py", line 49, in build_graph
    return Graph(nodes, edges)
  File "C:\Users\ABDUL REHMAN\AppData\Local\Programs\Python\Python310\lib\site-packages\langflow\graph\graph.py", line 43, in __init__
    self._build_graph()
  File "C:\Users\ABDUL REHMAN\AppData\Local\Programs\Python\Python310\lib\site-packages\langflow\graph\graph.py", line 56, in _build_graph
    node._build_params()
  File "C:\Users\ABDUL REHMAN\AppData\Local\Programs\Python\Python310\lib\site-packages\langflow\graph\base.py", line 94, in _build_params
    file_path = cache_utils.save_binary_file(
  File "C:\Users\ABDUL REHMAN\AppData\Local\Programs\Python\Python310\lib\site-packages\langflow\cache\base.py", line 25, in wrapper
    return func(*args, **kwargs)
  File "C:\Users\ABDUL REHMAN\AppData\Local\Programs\Python\Python310\lib\site-packages\langflow\cache\base.py", line 118, in save_binary_file
    raise ValueError(f"File {file_name} is not accepted")
ValueError: File  is not accepted
2023-05-05 19:27:16,832 - ERROR - File  is not accepted
Traceback (most recent call last):
  File "C:\Users\ABDUL REHMAN\AppData\Local\Programs\Python\Python310\lib\site-packages\langflow\api\validate.py", line 44, in post_validate_node
    graph = build_graph(data)
  File "C:\Users\ABDUL REHMAN\AppData\Local\Programs\Python\Python310\lib\site-packages\langflow\interface\run.py", line 49, in build_graph
    return Graph(nodes, edges)
  File "C:\Users\ABDUL REHMAN\AppData\Local\Programs\Python\Python310\lib\site-packages\langflow\graph\graph.py", line 43, in __init__
    self._build_graph()
  File "C:\Users\ABDUL REHMAN\AppData\Local\Programs\Python\Python310\lib\site-packages\langflow\graph\graph.py", line 56, in _build_graph
    node._build_params()
  File "C:\Users\ABDUL REHMAN\AppData\Local\Programs\Python\Python310\lib\site-packages\langflow\graph\base.py", line 94, in _build_params
    file_path = cache_utils.save_binary_file(
  File "C:\Users\ABDUL REHMAN\AppData\Local\Programs\Python\Python310\lib\site-packages\langflow\cache\base.py", line 25, in wrapper
    return func(*args, **kwargs)
  File "C:\Users\ABDUL REHMAN\AppData\Local\Programs\Python\Python310\lib\site-packages\langflow\cache\base.py", line 118, in save_binary_file
    raise ValueError(f"File {file_name} is not accepted")
ValueError: File  is not accepted
2023-05-05 19:27:16,832 - ERROR - File  is not accepted
Traceback (most recent call last):
  File "C:\Users\ABDUL REHMAN\AppData\Local\Programs\Python\Python310\lib\site-packages\langflow\api\validate.py", line 44, in post_validate_node
    graph = build_graph(data)
  File "C:\Users\ABDUL REHMAN\AppData\Local\Programs\Python\Python310\lib\site-packages\langflow\interface\run.py", line 49, in build_graph
    return Graph(nodes, edges)
  File "C:\Users\ABDUL REHMAN\AppData\Local\Programs\Python\Python310\lib\site-packages\langflow\graph\graph.py", line 43, in __init__
    self._build_graph()
  File "C:\Users\ABDUL REHMAN\AppData\Local\Programs\Python\Python310\lib\site-packages\langflow\graph\graph.py", line 56, in _build_graph
    node._build_params()
  File "C:\Users\ABDUL REHMAN\AppData\Local\Programs\Python\Python310\lib\site-packages\langflow\graph\base.py", line 94, in _build_params
    file_path = cache_utils.save_binary_file(
  File "C:\Users\ABDUL REHMAN\AppData\Local\Programs\Python\Python310\lib\site-packages\langflow\cache\base.py", line 25, in wrapper
    return func(*args, **kwargs)
  File "C:\Users\ABDUL REHMAN\AppData\Local\Programs\Python\Python310\lib\site-packages\langflow\cache\base.py", line 118, in save_binary_file
    raise ValueError(f"File {file_name} is not accepted")
ValueError: File  is not accepted
2023-05-05 19:27:17,231 - ERROR - File  is not accepted
Traceback (most recent call last):
  File "C:\Users\ABDUL REHMAN\AppData\Local\Programs\Python\Python310\lib\site-packages\langflow\api\validate.py", line 44, in post_validate_node
    graph = build_graph(data)
  File "C:\Users\ABDUL REHMAN\AppData\Local\Programs\Python\Python310\lib\site-packages\langflow\interface\run.py", line 49, in build_graph
    return Graph(nodes, edges)
  File "C:\Users\ABDUL REHMAN\AppData\Local\Programs\Python\Python310\lib\site-packages\langflow\graph\graph.py", line 43, in __init__
    self._build_graph()
  File "C:\Users\ABDUL REHMAN\AppData\Local\Programs\Python\Python310\lib\site-packages\langflow\graph\graph.py", line 56, in _build_graph
    node._build_params()
  File "C:\Users\ABDUL REHMAN\AppData\Local\Programs\Python\Python310\lib\site-packages\langflow\graph\base.py", line 94, in _build_params
    file_path = cache_utils.save_binary_file(
  File "C:\Users\ABDUL REHMAN\AppData\Local\Programs\Python\Python310\lib\site-packages\langflow\cache\base.py", line 25, in wrapper
    return func(*args, **kwargs)
  File "C:\Users\ABDUL REHMAN\AppData\Local\Programs\Python\Python310\lib\site-packages\langflow\cache\base.py", line 118, in save_binary_file
    raise ValueError(f"File {file_name} is not accepted")
ValueError: File  is not accepted
2023-05-05 19:27:17,511 - ERROR - File  is not accepted
Traceback (most recent call last):
  File "C:\Users\ABDUL REHMAN\AppData\Local\Programs\Python\Python310\lib\site-packages\langflow\api\validate.py", line 44, in post_validate_node
    graph = build_graph(data)
  File "C:\Users\ABDUL REHMAN\AppData\Local\Programs\Python\Python310\lib\site-packages\langflow\interface\run.py", line 49, in build_graph
    return Graph(nodes, edges)
  File "C:\Users\ABDUL REHMAN\AppData\Local\Programs\Python\Python310\lib\site-packages\langflow\graph\graph.py", line 43, in __init__
    self._build_graph()
  File "C:\Users\ABDUL REHMAN\AppData\Local\Programs\Python\Python310\lib\site-packages\langflow\graph\graph.py", line 56, in _build_graph
    node._build_params()
  File "C:\Users\ABDUL REHMAN\AppData\Local\Programs\Python\Python310\lib\site-packages\langflow\graph\base.py", line 94, in _build_params
    file_path = cache_utils.save_binary_file(
  File "C:\Users\ABDUL REHMAN\AppData\Local\Programs\Python\Python310\lib\site-packages\langflow\cache\base.py", line 25, in wrapper
    return func(*args, **kwargs)
  File "C:\Users\ABDUL REHMAN\AppData\Local\Programs\Python\Python310\lib\site-packages\langflow\cache\base.py", line 118, in save_binary_file
    raise ValueError(f"File {file_name} is not accepted")
ValueError: File  is not accepted
2023-05-05 19:27:17,619 - ERROR - File  is not accepted
Traceback (most recent call last):
  File "C:\Users\ABDUL REHMAN\AppData\Local\Programs\Python\Python310\lib\site-packages\langflow\api\validate.py", line 44, in post_validate_node
    graph = build_graph(data)
  File "C:\Users\ABDUL REHMAN\AppData\Local\Programs\Python\Python310\lib\site-packages\langflow\interface\run.py", line 49, in build_graph
    return Graph(nodes, edges)
  File "C:\Users\ABDUL REHMAN\AppData\Local\Programs\Python\Python310\lib\site-packages\langflow\graph\graph.py", line 43, in __init__
    self._build_graph()
  File "C:\Users\ABDUL REHMAN\AppData\Local\Programs\Python\Python310\lib\site-packages\langflow\graph\graph.py", line 56, in _build_graph
    node._build_params()
  File "C:\Users\ABDUL REHMAN\AppData\Local\Programs\Python\Python310\lib\site-packages\langflow\graph\base.py", line 94, in _build_params
    file_path = cache_utils.save_binary_file(
  File "C:\Users\ABDUL REHMAN\AppData\Local\Programs\Python\Python310\lib\site-packages\langflow\cache\base.py", line 25, in wrapper
    return func(*args, **kwargs)
  File "C:\Users\ABDUL REHMAN\AppData\Local\Programs\Python\Python310\lib\site-packages\langflow\cache\base.py", line 118, in save_binary_file
    raise ValueError(f"File {file_name} is not accepted")
ValueError: File  is not accepted
2023-05-05 19:27:17,799 - ERROR - File  is not accepted
Traceback (most recent call last):
  File "C:\Users\ABDUL REHMAN\AppData\Local\Programs\Python\Python310\lib\site-packages\langflow\api\validate.py", line 44, in post_validate_node
    graph = build_graph(data)
  File "C:\Users\ABDUL REHMAN\AppData\Local\Programs\Python\Python310\lib\site-packages\langflow\interface\run.py", line 49, in build_graph
    return Graph(nodes, edges)
  File "C:\Users\ABDUL REHMAN\AppData\Local\Programs\Python\Python310\lib\site-packages\langflow\graph\graph.py", line 43, in __init__
    self._build_graph()
  File "C:\Users\ABDUL REHMAN\AppData\Local\Programs\Python\Python310\lib\site-packages\langflow\graph\graph.py", line 56, in _build_graph
    node._build_params()
  File "C:\Users\ABDUL REHMAN\AppData\Local\Programs\Python\Python310\lib\site-packages\langflow\graph\base.py", line 94, in _build_params
    file_path = cache_utils.save_binary_file(
  File "C:\Users\ABDUL REHMAN\AppData\Local\Programs\Python\Python310\lib\site-packages\langflow\cache\base.py", line 25, in wrapper
    return func(*args, **kwargs)
  File "C:\Users\ABDUL REHMAN\AppData\Local\Programs\Python\Python310\lib\site-packages\langflow\cache\base.py", line 118, in save_binary_file
    raise ValueError(f"File {file_name} is not accepted")
ValueError: File  is not accepted
2023-05-05 19:27:17,969 - ERROR - File  is not accepted
Traceback (most recent call last):
  File "C:\Users\ABDUL REHMAN\AppData\Local\Programs\Python\Python310\lib\site-packages\langflow\api\validate.py", line 44, in post_validate_node
    graph = build_graph(data)
  File "C:\Users\ABDUL REHMAN\AppData\Local\Programs\Python\Python310\lib\site-packages\langflow\interface\run.py", line 49, in build_graph
    return Graph(nodes, edges)
  File "C:\Users\ABDUL REHMAN\AppData\Local\Programs\Python\Python310\lib\site-packages\langflow\graph\graph.py", line 43, in __init__
    self._build_graph()
  File "C:\Users\ABDUL REHMAN\AppData\Local\Programs\Python\Python310\lib\site-packages\langflow\graph\graph.py", line 56, in _build_graph
    node._build_params()
  File "C:\Users\ABDUL REHMAN\AppData\Local\Programs\Python\Python310\lib\site-packages\langflow\graph\base.py", line 94, in _build_params
    file_path = cache_utils.save_binary_file(
  File "C:\Users\ABDUL REHMAN\AppData\Local\Programs\Python\Python310\lib\site-packages\langflow\cache\base.py", line 25, in wrapper
    return func(*args, **kwargs)
  File "C:\Users\ABDUL REHMAN\AppData\Local\Programs\Python\Python310\lib\site-packages\langflow\cache\base.py", line 118, in save_binary_file
    raise ValueError(f"File {file_name} is not accepted")
ValueError: File  is not accepted
2023-05-05 19:27:18,091 - ERROR - File  is not accepted
Traceback (most recent call last):
  File "C:\Users\ABDUL REHMAN\AppData\Local\Programs\Python\Python310\lib\site-packages\langflow\api\validate.py", line 44, in post_validate_node
    graph = build_graph(data)
  File "C:\Users\ABDUL REHMAN\AppData\Local\Programs\Python\Python310\lib\site-packages\langflow\interface\run.py", line 49, in build_graph
    return Graph(nodes, edges)
  File "C:\Users\ABDUL REHMAN\AppData\Local\Programs\Python\Python310\lib\site-packages\langflow\graph\graph.py", line 43, in __init__
    self._build_graph()
  File "C:\Users\ABDUL REHMAN\AppData\Local\Programs\Python\Python310\lib\site-packages\langflow\graph\graph.py", line 56, in _build_graph
    node._build_params()
  File "C:\Users\ABDUL REHMAN\AppData\Local\Programs\Python\Python310\lib\site-packages\langflow\graph\base.py", line 94, in _build_params
    file_path = cache_utils.save_binary_file(
  File "C:\Users\ABDUL REHMAN\AppData\Local\Programs\Python\Python310\lib\site-packages\langflow\cache\base.py", line 25, in wrapper
    return func(*args, **kwargs)
  File "C:\Users\ABDUL REHMAN\AppData\Local\Programs\Python\Python310\lib\site-packages\langflow\cache\base.py", line 118, in save_binary_file
    raise ValueError(f"File {file_name} is not accepted")
ValueError: File  is not accepted
2023-05-05 19:27:23,081 - ERROR - File  is not accepted
Traceback (most recent call last):
  File "C:\Users\ABDUL REHMAN\AppData\Local\Programs\Python\Python310\lib\site-packages\langflow\api\validate.py", line 44, in post_validate_node
    graph = build_graph(data)
  File "C:\Users\ABDUL REHMAN\AppData\Local\Programs\Python\Python310\lib\site-packages\langflow\interface\run.py", line 49, in build_graph
    return Graph(nodes, edges)
  File "C:\Users\ABDUL REHMAN\AppData\Local\Programs\Python\Python310\lib\site-packages\langflow\graph\graph.py", line 43, in __init__
    self._build_graph()
  File "C:\Users\ABDUL REHMAN\AppData\Local\Programs\Python\Python310\lib\site-packages\langflow\graph\graph.py", line 56, in _build_graph
    node._build_params()
  File "C:\Users\ABDUL REHMAN\AppData\Local\Programs\Python\Python310\lib\site-packages\langflow\graph\base.py", line 94, in _build_params
    file_path = cache_utils.save_binary_file(
  File "C:\Users\ABDUL REHMAN\AppData\Local\Programs\Python\Python310\lib\site-packages\langflow\cache\base.py", line 25, in wrapper
    return func(*args, **kwargs)
  File "C:\Users\ABDUL REHMAN\AppData\Local\Programs\Python\Python310\lib\site-packages\langflow\cache\base.py", line 118, in save_binary_file
    raise ValueError(f"File {file_name} is not accepted")
ValueError: File  is not accepted
2023-05-05 19:27:23,098 - ERROR - File  is not accepted
Traceback (most recent call last):
  File "C:\Users\ABDUL REHMAN\AppData\Local\Programs\Python\Python310\lib\site-packages\langflow\api\validate.py", line 44, in post_validate_node
    graph = build_graph(data)
  File "C:\Users\ABDUL REHMAN\AppData\Local\Programs\Python\Python310\lib\site-packages\langflow\interface\run.py", line 49, in build_graph
    return Graph(nodes, edges)
  File "C:\Users\ABDUL REHMAN\AppData\Local\Programs\Python\Python310\lib\site-packages\langflow\graph\graph.py", line 43, in __init__
    self._build_graph()
  File "C:\Users\ABDUL REHMAN\AppData\Local\Programs\Python\Python310\lib\site-packages\langflow\graph\graph.py", line 56, in _build_graph
    node._build_params()
  File "C:\Users\ABDUL REHMAN\AppData\Local\Programs\Python\Python310\lib\site-packages\langflow\graph\base.py", line 94, in _build_params
    file_path = cache_utils.save_binary_file(
  File "C:\Users\ABDUL REHMAN\AppData\Local\Programs\Python\Python310\lib\site-packages\langflow\cache\base.py", line 25, in wrapper
    return func(*args, **kwargs)
  File "C:\Users\ABDUL REHMAN\AppData\Local\Programs\Python\Python310\lib\site-packages\langflow\cache\base.py", line 118, in save_binary_file
    raise ValueError(f"File {file_name} is not accepted")
ValueError: File  is not accepted
2023-05-05 19:27:23,098 - ERROR - File  is not accepted
Traceback (most recent call last):
  File "C:\Users\ABDUL REHMAN\AppData\Local\Programs\Python\Python310\lib\site-packages\langflow\api\validate.py", line 44, in post_validate_node
    graph = build_graph(data)
  File "C:\Users\ABDUL REHMAN\AppData\Local\Programs\Python\Python310\lib\site-packages\langflow\interface\run.py", line 49, in build_graph
    return Graph(nodes, edges)
  File "C:\Users\ABDUL REHMAN\AppData\Local\Programs\Python\Python310\lib\site-packages\langflow\graph\graph.py", line 43, in __init__
    self._build_graph()
  File "C:\Users\ABDUL REHMAN\AppData\Local\Programs\Python\Python310\lib\site-packages\langflow\graph\graph.py", line 56, in _build_graph
    node._build_params()
  File "C:\Users\ABDUL REHMAN\AppData\Local\Programs\Python\Python310\lib\site-packages\langflow\graph\base.py", line 94, in _build_params
    file_path = cache_utils.save_binary_file(
  File "C:\Users\ABDUL REHMAN\AppData\Local\Programs\Python\Python310\lib\site-packages\langflow\cache\base.py", line 25, in wrapper
    return func(*args, **kwargs)
  File "C:\Users\ABDUL REHMAN\AppData\Local\Programs\Python\Python310\lib\site-packages\langflow\cache\base.py", line 118, in save_binary_file
    raise ValueError(f"File {file_name} is not accepted")
ValueError: File  is not accepted
2023-05-05 19:27:23,098 - ERROR - File  is not accepted
Traceback (most recent call last):
  File "C:\Users\ABDUL REHMAN\AppData\Local\Programs\Python\Python310\lib\site-packages\langflow\api\validate.py", line 44, in post_validate_node
    graph = build_graph(data)
  File "C:\Users\ABDUL REHMAN\AppData\Local\Programs\Python\Python310\lib\site-packages\langflow\interface\run.py", line 49, in build_graph
    return Graph(nodes, edges)
  File "C:\Users\ABDUL REHMAN\AppData\Local\Programs\Python\Python310\lib\site-packages\langflow\graph\graph.py", line 43, in __init__
    self._build_graph()
  File "C:\Users\ABDUL REHMAN\AppData\Local\Programs\Python\Python310\lib\site-packages\langflow\graph\graph.py", line 56, in _build_graph
    node._build_params()
  File "C:\Users\ABDUL REHMAN\AppData\Local\Programs\Python\Python310\lib\site-packages\langflow\graph\base.py", line 94, in _build_params
    file_path = cache_utils.save_binary_file(
  File "C:\Users\ABDUL REHMAN\AppData\Local\Programs\Python\Python310\lib\site-packages\langflow\cache\base.py", line 25, in wrapper
    return func(*args, **kwargs)
  File "C:\Users\ABDUL REHMAN\AppData\Local\Programs\Python\Python310\lib\site-packages\langflow\cache\base.py", line 118, in save_binary_file
    raise ValueError(f"File {file_name} is not accepted")
ValueError: File  is not accepted
2023-05-05 19:27:23,271 - ERROR - File  is not accepted
Traceback (most recent call last):
  File "C:\Users\ABDUL REHMAN\AppData\Local\Programs\Python\Python310\lib\site-packages\langflow\api\validate.py", line 44, in post_validate_node
    graph = build_graph(data)
  File "C:\Users\ABDUL REHMAN\AppData\Local\Programs\Python\Python310\lib\site-packages\langflow\interface\run.py", line 49, in build_graph
    return Graph(nodes, edges)
  File "C:\Users\ABDUL REHMAN\AppData\Local\Programs\Python\Python310\lib\site-packages\langflow\graph\graph.py", line 43, in __init__
    self._build_graph()
  File "C:\Users\ABDUL REHMAN\AppData\Local\Programs\Python\Python310\lib\site-packages\langflow\graph\graph.py", line 56, in _build_graph
    node._build_params()
  File "C:\Users\ABDUL REHMAN\AppData\Local\Programs\Python\Python310\lib\site-packages\langflow\graph\base.py", line 94, in _build_params
    file_path = cache_utils.save_binary_file(
  File "C:\Users\ABDUL REHMAN\AppData\Local\Programs\Python\Python310\lib\site-packages\langflow\cache\base.py", line 25, in wrapper
    return func(*args, **kwargs)
  File "C:\Users\ABDUL REHMAN\AppData\Local\Programs\Python\Python310\lib\site-packages\langflow\cache\base.py", line 118, in save_binary_file
    raise ValueError(f"File {file_name} is not accepted")
ValueError: File  is not accepted
2023-05-05 19:27:23,271 - ERROR - File  is not accepted
Traceback (most recent call last):
  File "C:\Users\ABDUL REHMAN\AppData\Local\Programs\Python\Python310\lib\site-packages\langflow\api\validate.py", line 44, in post_validate_node
    graph = build_graph(data)
  File "C:\Users\ABDUL REHMAN\AppData\Local\Programs\Python\Python310\lib\site-packages\langflow\interface\run.py", line 49, in build_graph
    return Graph(nodes, edges)
  File "C:\Users\ABDUL REHMAN\AppData\Local\Programs\Python\Python310\lib\site-packages\langflow\graph\graph.py", line 43, in __init__
    self._build_graph()
  File "C:\Users\ABDUL REHMAN\AppData\Local\Programs\Python\Python310\lib\site-packages\langflow\graph\graph.py", line 56, in _build_graph
    node._build_params()
  File "C:\Users\ABDUL REHMAN\AppData\Local\Programs\Python\Python310\lib\site-packages\langflow\graph\base.py", line 94, in _build_params
    file_path = cache_utils.save_binary_file(
  File "C:\Users\ABDUL REHMAN\AppData\Local\Programs\Python\Python310\lib\site-packages\langflow\cache\base.py", line 25, in wrapper
    return func(*args, **kwargs)
  File "C:\Users\ABDUL REHMAN\AppData\Local\Programs\Python\Python310\lib\site-packages\langflow\cache\base.py", line 118, in save_binary_file
    raise ValueError(f"File {file_name} is not accepted")
ValueError: File  is not accepted
2023-05-05 19:27:23,286 - ERROR - File  is not accepted
Traceback (most recent call last):
  File "C:\Users\ABDUL REHMAN\AppData\Local\Programs\Python\Python310\lib\site-packages\langflow\api\validate.py", line 44, in post_validate_node
    graph = build_graph(data)
  File "C:\Users\ABDUL REHMAN\AppData\Local\Programs\Python\Python310\lib\site-packages\langflow\interface\run.py", line 49, in build_graph
    return Graph(nodes, edges)
  File "C:\Users\ABDUL REHMAN\AppData\Local\Programs\Python\Python310\lib\site-packages\langflow\graph\graph.py", line 43, in __init__
    self._build_graph()
  File "C:\Users\ABDUL REHMAN\AppData\Local\Programs\Python\Python310\lib\site-packages\langflow\graph\graph.py", line 56, in _build_graph
    node._build_params()
  File "C:\Users\ABDUL REHMAN\AppData\Local\Programs\Python\Python310\lib\site-packages\langflow\graph\base.py", line 94, in _build_params
    file_path = cache_utils.save_binary_file(
  File "C:\Users\ABDUL REHMAN\AppData\Local\Programs\Python\Python310\lib\site-packages\langflow\cache\base.py", line 25, in wrapper
    return func(*args, **kwargs)
  File "C:\Users\ABDUL REHMAN\AppData\Local\Programs\Python\Python310\lib\site-packages\langflow\cache\base.py", line 118, in save_binary_file
    raise ValueError(f"File {file_name} is not accepted")
ValueError: File  is not accepted
2023-05-05 19:27:23,492 - ERROR - File  is not accepted
Traceback (most recent call last):
  File "C:\Users\ABDUL REHMAN\AppData\Local\Programs\Python\Python310\lib\site-packages\langflow\api\validate.py", line 44, in post_validate_node
    graph = build_graph(data)
  File "C:\Users\ABDUL REHMAN\AppData\Local\Programs\Python\Python310\lib\site-packages\langflow\interface\run.py", line 49, in build_graph
    return Graph(nodes, edges)
  File "C:\Users\ABDUL REHMAN\AppData\Local\Programs\Python\Python310\lib\site-packages\langflow\graph\graph.py", line 43, in __init__
    self._build_graph()
  File "C:\Users\ABDUL REHMAN\AppData\Local\Programs\Python\Python310\lib\site-packages\langflow\graph\graph.py", line 56, in _build_graph
    node._build_params()
  File "C:\Users\ABDUL REHMAN\AppData\Local\Programs\Python\Python310\lib\site-packages\langflow\graph\base.py", line 94, in _build_params
    file_path = cache_utils.save_binary_file(
  File "C:\Users\ABDUL REHMAN\AppData\Local\Programs\Python\Python310\lib\site-packages\langflow\cache\base.py", line 25, in wrapper
    return func(*args, **kwargs)
  File "C:\Users\ABDUL REHMAN\AppData\Local\Programs\Python\Python310\lib\site-packages\langflow\cache\base.py", line 118, in save_binary_file
    raise ValueError(f"File {file_name} is not accepted")
ValueError: File  is not accepted
2023-05-05 19:27:23,626 - ERROR - File  is not accepted
Traceback (most recent call last):
  File "C:\Users\ABDUL REHMAN\AppData\Local\Programs\Python\Python310\lib\site-packages\langflow\api\validate.py", line 44, in post_validate_node
    graph = build_graph(data)
  File "C:\Users\ABDUL REHMAN\AppData\Local\Programs\Python\Python310\lib\site-packages\langflow\interface\run.py", line 49, in build_graph
    return Graph(nodes, edges)
  File "C:\Users\ABDUL REHMAN\AppData\Local\Programs\Python\Python310\lib\site-packages\langflow\graph\graph.py", line 43, in __init__
    self._build_graph()
  File "C:\Users\ABDUL REHMAN\AppData\Local\Programs\Python\Python310\lib\site-packages\langflow\graph\graph.py", line 56, in _build_graph
    node._build_params()
  File "C:\Users\ABDUL REHMAN\AppData\Local\Programs\Python\Python310\lib\site-packages\langflow\graph\base.py", line 94, in _build_params
    file_path = cache_utils.save_binary_file(
  File "C:\Users\ABDUL REHMAN\AppData\Local\Programs\Python\Python310\lib\site-packages\langflow\cache\base.py", line 25, in wrapper
    return func(*args, **kwargs)
  File "C:\Users\ABDUL REHMAN\AppData\Local\Programs\Python\Python310\lib\site-packages\langflow\cache\base.py", line 118, in save_binary_file
    raise ValueError(f"File {file_name} is not accepted")
ValueError: File  is not accepted
2023-05-05 19:27:23,824 - ERROR - File  is not accepted
Traceback (most recent call last):
  File "C:\Users\ABDUL REHMAN\AppData\Local\Programs\Python\Python310\lib\site-packages\langflow\api\validate.py", line 44, in post_validate_node
    graph = build_graph(data)
  File "C:\Users\ABDUL REHMAN\AppData\Local\Programs\Python\Python310\lib\site-packages\langflow\interface\run.py", line 49, in build_graph
    return Graph(nodes, edges)
  File "C:\Users\ABDUL REHMAN\AppData\Local\Programs\Python\Python310\lib\site-packages\langflow\graph\graph.py", line 43, in __init__
    self._build_graph()
  File "C:\Users\ABDUL REHMAN\AppData\Local\Programs\Python\Python310\lib\site-packages\langflow\graph\graph.py", line 56, in _build_graph
    node._build_params()
  File "C:\Users\ABDUL REHMAN\AppData\Local\Programs\Python\Python310\lib\site-packages\langflow\graph\base.py", line 94, in _build_params
    file_path = cache_utils.save_binary_file(
  File "C:\Users\ABDUL REHMAN\AppData\Local\Programs\Python\Python310\lib\site-packages\langflow\cache\base.py", line 25, in wrapper
    return func(*args, **kwargs)
  File "C:\Users\ABDUL REHMAN\AppData\Local\Programs\Python\Python310\lib\site-packages\langflow\cache\base.py", line 118, in save_binary_file
    raise ValueError(f"File {file_name} is not accepted")
ValueError: File  is not accepted
2023-05-05 19:27:24,001 - ERROR - File  is not accepted
Traceback (most recent call last):
  File "C:\Users\ABDUL REHMAN\AppData\Local\Programs\Python\Python310\lib\site-packages\langflow\api\validate.py", line 44, in post_validate_node
    graph = build_graph(data)
  File "C:\Users\ABDUL REHMAN\AppData\Local\Programs\Python\Python310\lib\site-packages\langflow\interface\run.py", line 49, in build_graph
    return Graph(nodes, edges)
  File "C:\Users\ABDUL REHMAN\AppData\Local\Programs\Python\Python310\lib\site-packages\langflow\graph\graph.py", line 43, in __init__
    self._build_graph()
  File "C:\Users\ABDUL REHMAN\AppData\Local\Programs\Python\Python310\lib\site-packages\langflow\graph\graph.py", line 56, in _build_graph
    node._build_params()
  File "C:\Users\ABDUL REHMAN\AppData\Local\Programs\Python\Python310\lib\site-packages\langflow\graph\base.py", line 94, in _build_params
    file_path = cache_utils.save_binary_file(
  File "C:\Users\ABDUL REHMAN\AppData\Local\Programs\Python\Python310\lib\site-packages\langflow\cache\base.py", line 25, in wrapper
    return func(*args, **kwargs)
  File "C:\Users\ABDUL REHMAN\AppData\Local\Programs\Python\Python310\lib\site-packages\langflow\cache\base.py", line 118, in save_binary_file
    raise ValueError(f"File {file_name} is not accepted")
ValueError: File  is not accepted
2023-05-05 19:27:24,134 - ERROR - File  is not accepted
Traceback (most recent call last):
  File "C:\Users\ABDUL REHMAN\AppData\Local\Programs\Python\Python310\lib\site-packages\langflow\api\validate.py", line 44, in post_validate_node
    graph = build_graph(data)
  File "C:\Users\ABDUL REHMAN\AppData\Local\Programs\Python\Python310\lib\site-packages\langflow\interface\run.py", line 49, in build_graph
    return Graph(nodes, edges)
  File "C:\Users\ABDUL REHMAN\AppData\Local\Programs\Python\Python310\lib\site-packages\langflow\graph\graph.py", line 43, in __init__
    self._build_graph()
  File "C:\Users\ABDUL REHMAN\AppData\Local\Programs\Python\Python310\lib\site-packages\langflow\graph\graph.py", line 56, in _build_graph
    node._build_params()
  File "C:\Users\ABDUL REHMAN\AppData\Local\Programs\Python\Python310\lib\site-packages\langflow\graph\base.py", line 94, in _build_params
    file_path = cache_utils.save_binary_file(
  File "C:\Users\ABDUL REHMAN\AppData\Local\Programs\Python\Python310\lib\site-packages\langflow\cache\base.py", line 25, in wrapper
    return func(*args, **kwargs)
  File "C:\Users\ABDUL REHMAN\AppData\Local\Programs\Python\Python310\lib\site-packages\langflow\cache\base.py", line 118, in save_binary_file
    raise ValueError(f"File {file_name} is not accepted")
ValueError: File  is not accepted
2023-05-05 19:27:24,331 - ERROR - File  is not accepted
Traceback (most recent call last):
  File "C:\Users\ABDUL REHMAN\AppData\Local\Programs\Python\Python310\lib\site-packages\langflow\api\validate.py", line 44, in post_validate_node
    graph = build_graph(data)
  File "C:\Users\ABDUL REHMAN\AppData\Local\Programs\Python\Python310\lib\site-packages\langflow\interface\run.py", line 49, in build_graph
    return Graph(nodes, edges)
  File "C:\Users\ABDUL REHMAN\AppData\Local\Programs\Python\Python310\lib\site-packages\langflow\graph\graph.py", line 43, in __init__
    self._build_graph()
  File "C:\Users\ABDUL REHMAN\AppData\Local\Programs\Python\Python310\lib\site-packages\langflow\graph\graph.py", line 56, in _build_graph
    node._build_params()
  File "C:\Users\ABDUL REHMAN\AppData\Local\Programs\Python\Python310\lib\site-packages\langflow\graph\base.py", line 94, in _build_params
    file_path = cache_utils.save_binary_file(
  File "C:\Users\ABDUL REHMAN\AppData\Local\Programs\Python\Python310\lib\site-packages\langflow\cache\base.py", line 25, in wrapper
    return func(*args, **kwargs)
  File "C:\Users\ABDUL REHMAN\AppData\Local\Programs\Python\Python310\lib\site-packages\langflow\cache\base.py", line 118, in save_binary_file
    raise ValueError(f"File {file_name} is not accepted")
ValueError: File  is not accepted
2023-05-05 19:27:24,481 - ERROR - File  is not accepted
Traceback (most recent call last):
  File "C:\Users\ABDUL REHMAN\AppData\Local\Programs\Python\Python310\lib\site-packages\langflow\api\validate.py", line 44, in post_validate_node
    graph = build_graph(data)
  File "C:\Users\ABDUL REHMAN\AppData\Local\Programs\Python\Python310\lib\site-packages\langflow\interface\run.py", line 49, in build_graph
    return Graph(nodes, edges)
  File "C:\Users\ABDUL REHMAN\AppData\Local\Programs\Python\Python310\lib\site-packages\langflow\graph\graph.py", line 43, in __init__
    self._build_graph()
  File "C:\Users\ABDUL REHMAN\AppData\Local\Programs\Python\Python310\lib\site-packages\langflow\graph\graph.py", line 56, in _build_graph
    node._build_params()
  File "C:\Users\ABDUL REHMAN\AppData\Local\Programs\Python\Python310\lib\site-packages\langflow\graph\base.py", line 94, in _build_params
    file_path = cache_utils.save_binary_file(
  File "C:\Users\ABDUL REHMAN\AppData\Local\Programs\Python\Python310\lib\site-packages\langflow\cache\base.py", line 25, in wrapper
    return func(*args, **kwargs)
  File "C:\Users\ABDUL REHMAN\AppData\Local\Programs\Python\Python310\lib\site-packages\langflow\cache\base.py", line 118, in save_binary_file
    raise ValueError(f"File {file_name} is not accepted")
ValueError: File  is not accepted
2023-05-05 19:27:24,638 - ERROR - File  is not accepted
Traceback (most recent call last):
  File "C:\Users\ABDUL REHMAN\AppData\Local\Programs\Python\Python310\lib\site-packages\langflow\api\validate.py", line 44, in post_validate_node
    graph = build_graph(data)
  File "C:\Users\ABDUL REHMAN\AppData\Local\Programs\Python\Python310\lib\site-packages\langflow\interface\run.py", line 49, in build_graph
    return Graph(nodes, edges)
  File "C:\Users\ABDUL REHMAN\AppData\Local\Programs\Python\Python310\lib\site-packages\langflow\graph\graph.py", line 43, in __init__
    self._build_graph()
  File "C:\Users\ABDUL REHMAN\AppData\Local\Programs\Python\Python310\lib\site-packages\langflow\graph\graph.py", line 56, in _build_graph
    node._build_params()
  File "C:\Users\ABDUL REHMAN\AppData\Local\Programs\Python\Python310\lib\site-packages\langflow\graph\base.py", line 94, in _build_params
    file_path = cache_utils.save_binary_file(
  File "C:\Users\ABDUL REHMAN\AppData\Local\Programs\Python\Python310\lib\site-packages\langflow\cache\base.py", line 25, in wrapper
    return func(*args, **kwargs)
  File "C:\Users\ABDUL REHMAN\AppData\Local\Programs\Python\Python310\lib\site-packages\langflow\cache\base.py", line 118, in save_binary_file
    raise ValueError(f"File {file_name} is not accepted")
ValueError: File  is not accepted
2023-05-05 19:27:24,857 - ERROR - File  is not accepted
Traceback (most recent call last):
  File "C:\Users\ABDUL REHMAN\AppData\Local\Programs\Python\Python310\lib\site-packages\langflow\api\validate.py", line 44, in post_validate_node
    graph = build_graph(data)
  File "C:\Users\ABDUL REHMAN\AppData\Local\Programs\Python\Python310\lib\site-packages\langflow\interface\run.py", line 49, in build_graph
    return Graph(nodes, edges)
  File "C:\Users\ABDUL REHMAN\AppData\Local\Programs\Python\Python310\lib\site-packages\langflow\graph\graph.py", line 43, in __init__
    self._build_graph()
  File "C:\Users\ABDUL REHMAN\AppData\Local\Programs\Python\Python310\lib\site-packages\langflow\graph\graph.py", line 56, in _build_graph
    node._build_params()
  File "C:\Users\ABDUL REHMAN\AppData\Local\Programs\Python\Python310\lib\site-packages\langflow\graph\base.py", line 94, in _build_params
    file_path = cache_utils.save_binary_file(
  File "C:\Users\ABDUL REHMAN\AppData\Local\Programs\Python\Python310\lib\site-packages\langflow\cache\base.py", line 25, in wrapper
    return func(*args, **kwargs)
  File "C:\Users\ABDUL REHMAN\AppData\Local\Programs\Python\Python310\lib\site-packages\langflow\cache\base.py", line 118, in save_binary_file
    raise ValueError(f"File {file_name} is not accepted")
ValueError: File  is not accepted
2023-05-05 19:27:25,023 - ERROR - File  is not accepted
Traceback (most recent call last):
  File "C:\Users\ABDUL REHMAN\AppData\Local\Programs\Python\Python310\lib\site-packages\langflow\api\validate.py", line 44, in post_validate_node
    graph = build_graph(data)
  File "C:\Users\ABDUL REHMAN\AppData\Local\Programs\Python\Python310\lib\site-packages\langflow\interface\run.py", line 49, in build_graph
    return Graph(nodes, edges)
  File "C:\Users\ABDUL REHMAN\AppData\Local\Programs\Python\Python310\lib\site-packages\langflow\graph\graph.py", line 43, in __init__
    self._build_graph()
  File "C:\Users\ABDUL REHMAN\AppData\Local\Programs\Python\Python310\lib\site-packages\langflow\graph\graph.py", line 56, in _build_graph
    node._build_params()
  File "C:\Users\ABDUL REHMAN\AppData\Local\Programs\Python\Python310\lib\site-packages\langflow\graph\base.py", line 94, in _build_params
    file_path = cache_utils.save_binary_file(
  File "C:\Users\ABDUL REHMAN\AppData\Local\Programs\Python\Python310\lib\site-packages\langflow\cache\base.py", line 25, in wrapper
    return func(*args, **kwargs)
  File "C:\Users\ABDUL REHMAN\AppData\Local\Programs\Python\Python310\lib\site-packages\langflow\cache\base.py", line 118, in save_binary_file
    raise ValueError(f"File {file_name} is not accepted")
ValueError: File  is not accepted
2023-05-05 19:27:25,204 - ERROR - File  is not accepted
Traceback (most recent call last):
  File "C:\Users\ABDUL REHMAN\AppData\Local\Programs\Python\Python310\lib\site-packages\langflow\api\validate.py", line 44, in post_validate_node
    graph = build_graph(data)
  File "C:\Users\ABDUL REHMAN\AppData\Local\Programs\Python\Python310\lib\site-packages\langflow\interface\run.py", line 49, in build_graph
    return Graph(nodes, edges)
  File "C:\Users\ABDUL REHMAN\AppData\Local\Programs\Python\Python310\lib\site-packages\langflow\graph\graph.py", line 43, in __init__
    self._build_graph()
  File "C:\Users\ABDUL REHMAN\AppData\Local\Programs\Python\Python310\lib\site-packages\langflow\graph\graph.py", line 56, in _build_graph
    node._build_params()
  File "C:\Users\ABDUL REHMAN\AppData\Local\Programs\Python\Python310\lib\site-packages\langflow\graph\base.py", line 94, in _build_params
    file_path = cache_utils.save_binary_file(
  File "C:\Users\ABDUL REHMAN\AppData\Local\Programs\Python\Python310\lib\site-packages\langflow\cache\base.py", line 25, in wrapper
    return func(*args, **kwargs)
  File "C:\Users\ABDUL REHMAN\AppData\Local\Programs\Python\Python310\lib\site-packages\langflow\cache\base.py", line 118, in save_binary_file
    raise ValueError(f"File {file_name} is not accepted")
ValueError: File  is not accepted
2023-05-05 19:27:25,394 - ERROR - File  is not accepted
Traceback (most recent call last):
  File "C:\Users\ABDUL REHMAN\AppData\Local\Programs\Python\Python310\lib\site-packages\langflow\api\validate.py", line 44, in post_validate_node
    graph = build_graph(data)
  File "C:\Users\ABDUL REHMAN\AppData\Local\Programs\Python\Python310\lib\site-packages\langflow\interface\run.py", line 49, in build_graph
    return Graph(nodes, edges)
  File "C:\Users\ABDUL REHMAN\AppData\Local\Programs\Python\Python310\lib\site-packages\langflow\graph\graph.py", line 43, in __init__
    self._build_graph()
  File "C:\Users\ABDUL REHMAN\AppData\Local\Programs\Python\Python310\lib\site-packages\langflow\graph\graph.py", line 56, in _build_graph
    node._build_params()
  File "C:\Users\ABDUL REHMAN\AppData\Local\Programs\Python\Python310\lib\site-packages\langflow\graph\base.py", line 94, in _build_params
    file_path = cache_utils.save_binary_file(
  File "C:\Users\ABDUL REHMAN\AppData\Local\Programs\Python\Python310\lib\site-packages\langflow\cache\base.py", line 25, in wrapper
    return func(*args, **kwargs)
  File "C:\Users\ABDUL REHMAN\AppData\Local\Programs\Python\Python310\lib\site-packages\langflow\cache\base.py", line 118, in save_binary_file
    raise ValueError(f"File {file_name} is not accepted")
ValueError: File  is not accepted
2023-05-05 19:27:25,528 - ERROR - File  is not accepted
Traceback (most recent call last):
  File "C:\Users\ABDUL REHMAN\AppData\Local\Programs\Python\Python310\lib\site-packages\langflow\api\validate.py", line 44, in post_validate_node
    graph = build_graph(data)
  File "C:\Users\ABDUL REHMAN\AppData\Local\Programs\Python\Python310\lib\site-packages\langflow\interface\run.py", line 49, in build_graph
    return Graph(nodes, edges)
  File "C:\Users\ABDUL REHMAN\AppData\Local\Programs\Python\Python310\lib\site-packages\langflow\graph\graph.py", line 43, in __init__
    self._build_graph()
  File "C:\Users\ABDUL REHMAN\AppData\Local\Programs\Python\Python310\lib\site-packages\langflow\graph\graph.py", line 56, in _build_graph
    node._build_params()
  File "C:\Users\ABDUL REHMAN\AppData\Local\Programs\Python\Python310\lib\site-packages\langflow\graph\base.py", line 94, in _build_params
    file_path = cache_utils.save_binary_file(
  File "C:\Users\ABDUL REHMAN\AppData\Local\Programs\Python\Python310\lib\site-packages\langflow\cache\base.py", line 25, in wrapper
    return func(*args, **kwargs)
  File "C:\Users\ABDUL REHMAN\AppData\Local\Programs\Python\Python310\lib\site-packages\langflow\cache\base.py", line 118, in save_binary_file
    raise ValueError(f"File {file_name} is not accepted")
ValueError: File  is not accepted
2023-05-05 19:27:25,904 - ERROR - File  is not accepted
Traceback (most recent call last):
  File "C:\Users\ABDUL REHMAN\AppData\Local\Programs\Python\Python310\lib\site-packages\langflow\api\validate.py", line 44, in post_validate_node
    graph = build_graph(data)
  File "C:\Users\ABDUL REHMAN\AppData\Local\Programs\Python\Python310\lib\site-packages\langflow\interface\run.py", line 49, in build_graph
    return Graph(nodes, edges)
  File "C:\Users\ABDUL REHMAN\AppData\Local\Programs\Python\Python310\lib\site-packages\langflow\graph\graph.py", line 43, in __init__
    self._build_graph()
  File "C:\Users\ABDUL REHMAN\AppData\Local\Programs\Python\Python310\lib\site-packages\langflow\graph\graph.py", line 56, in _build_graph
    node._build_params()
  File "C:\Users\ABDUL REHMAN\AppData\Local\Programs\Python\Python310\lib\site-packages\langflow\graph\base.py", line 94, in _build_params
    file_path = cache_utils.save_binary_file(
  File "C:\Users\ABDUL REHMAN\AppData\Local\Programs\Python\Python310\lib\site-packages\langflow\cache\base.py", line 25, in wrapper
    return func(*args, **kwargs)
  File "C:\Users\ABDUL REHMAN\AppData\Local\Programs\Python\Python310\lib\site-packages\langflow\cache\base.py", line 118, in save_binary_file
    raise ValueError(f"File {file_name} is not accepted")
ValueError: File  is not accepted
2023-05-05 19:27:26,265 - ERROR - File  is not accepted
Traceback (most recent call last):
  File "C:\Users\ABDUL REHMAN\AppData\Local\Programs\Python\Python310\lib\site-packages\langflow\api\validate.py", line 44, in post_validate_node
    graph = build_graph(data)
  File "C:\Users\ABDUL REHMAN\AppData\Local\Programs\Python\Python310\lib\site-packages\langflow\interface\run.py", line 49, in build_graph
    return Graph(nodes, edges)
  File "C:\Users\ABDUL REHMAN\AppData\Local\Programs\Python\Python310\lib\site-packages\langflow\graph\graph.py", line 43, in __init__
    self._build_graph()
  File "C:\Users\ABDUL REHMAN\AppData\Local\Programs\Python\Python310\lib\site-packages\langflow\graph\graph.py", line 56, in _build_graph
    node._build_params()
  File "C:\Users\ABDUL REHMAN\AppData\Local\Programs\Python\Python310\lib\site-packages\langflow\graph\base.py", line 94, in _build_params
    file_path = cache_utils.save_binary_file(
  File "C:\Users\ABDUL REHMAN\AppData\Local\Programs\Python\Python310\lib\site-packages\langflow\cache\base.py", line 25, in wrapper
    return func(*args, **kwargs)
  File "C:\Users\ABDUL REHMAN\AppData\Local\Programs\Python\Python310\lib\site-packages\langflow\cache\base.py", line 118, in save_binary_file
    raise ValueError(f"File {file_name} is not accepted")
ValueError: File  is not accepted
2023-05-05 19:27:26,421 - ERROR - File  is not accepted
Traceback (most recent call last):
  File "C:\Users\ABDUL REHMAN\AppData\Local\Programs\Python\Python310\lib\site-packages\langflow\api\validate.py", line 44, in post_validate_node
    graph = build_graph(data)
  File "C:\Users\ABDUL REHMAN\AppData\Local\Programs\Python\Python310\lib\site-packages\langflow\interface\run.py", line 49, in build_graph
    return Graph(nodes, edges)
  File "C:\Users\ABDUL REHMAN\AppData\Local\Programs\Python\Python310\lib\site-packages\langflow\graph\graph.py", line 43, in __init__
    self._build_graph()
  File "C:\Users\ABDUL REHMAN\AppData\Local\Programs\Python\Python310\lib\site-packages\langflow\graph\graph.py", line 56, in _build_graph
    node._build_params()
  File "C:\Users\ABDUL REHMAN\AppData\Local\Programs\Python\Python310\lib\site-packages\langflow\graph\base.py", line 94, in _build_params
    file_path = cache_utils.save_binary_file(
  File "C:\Users\ABDUL REHMAN\AppData\Local\Programs\Python\Python310\lib\site-packages\langflow\cache\base.py", line 25, in wrapper
    return func(*args, **kwargs)
  File "C:\Users\ABDUL REHMAN\AppData\Local\Programs\Python\Python310\lib\site-packages\langflow\cache\base.py", line 118, in save_binary_file
    raise ValueError(f"File {file_name} is not accepted")
ValueError: File  is not accepted
2023-05-05 19:27:26,729 - ERROR - File  is not accepted
Traceback (most recent call last):
  File "C:\Users\ABDUL REHMAN\AppData\Local\Programs\Python\Python310\lib\site-packages\langflow\api\validate.py", line 44, in post_validate_node
    graph = build_graph(data)
  File "C:\Users\ABDUL REHMAN\AppData\Local\Programs\Python\Python310\lib\site-packages\langflow\interface\run.py", line 49, in build_graph
    return Graph(nodes, edges)
  File "C:\Users\ABDUL REHMAN\AppData\Local\Programs\Python\Python310\lib\site-packages\langflow\graph\graph.py", line 43, in __init__
    self._build_graph()
  File "C:\Users\ABDUL REHMAN\AppData\Local\Programs\Python\Python310\lib\site-packages\langflow\graph\graph.py", line 56, in _build_graph
    node._build_params()
  File "C:\Users\ABDUL REHMAN\AppData\Local\Programs\Python\Python310\lib\site-packages\langflow\graph\base.py", line 94, in _build_params
    file_path = cache_utils.save_binary_file(
  File "C:\Users\ABDUL REHMAN\AppData\Local\Programs\Python\Python310\lib\site-packages\langflow\cache\base.py", line 25, in wrapper
    return func(*args, **kwargs)
  File "C:\Users\ABDUL REHMAN\AppData\Local\Programs\Python\Python310\lib\site-packages\langflow\cache\base.py", line 118, in save_binary_file
    raise ValueError(f"File {file_name} is not accepted")
ValueError: File  is not accepted
2023-05-05 19:27:26,787 - ERROR - File  is not accepted
Traceback (most recent call last):
  File "C:\Users\ABDUL REHMAN\AppData\Local\Programs\Python\Python310\lib\site-packages\langflow\api\validate.py", line 44, in post_validate_node
    graph = build_graph(data)
  File "C:\Users\ABDUL REHMAN\AppData\Local\Programs\Python\Python310\lib\site-packages\langflow\interface\run.py", line 49, in build_graph
    return Graph(nodes, edges)
  File "C:\Users\ABDUL REHMAN\AppData\Local\Programs\Python\Python310\lib\site-packages\langflow\graph\graph.py", line 43, in __init__
    self._build_graph()
  File "C:\Users\ABDUL REHMAN\AppData\Local\Programs\Python\Python310\lib\site-packages\langflow\graph\graph.py", line 56, in _build_graph
    node._build_params()
  File "C:\Users\ABDUL REHMAN\AppData\Local\Programs\Python\Python310\lib\site-packages\langflow\graph\base.py", line 94, in _build_params
    file_path = cache_utils.save_binary_file(
  File "C:\Users\ABDUL REHMAN\AppData\Local\Programs\Python\Python310\lib\site-packages\langflow\cache\base.py", line 25, in wrapper
    return func(*args, **kwargs)
  File "C:\Users\ABDUL REHMAN\AppData\Local\Programs\Python\Python310\lib\site-packages\langflow\cache\base.py", line 118, in save_binary_file
    raise ValueError(f"File {file_name} is not accepted")
ValueError: File  is not accepted
2023-05-05 19:27:26,991 - ERROR - File  is not accepted
Traceback (most recent call last):
  File "C:\Users\ABDUL REHMAN\AppData\Local\Programs\Python\Python310\lib\site-packages\langflow\api\validate.py", line 44, in post_validate_node
    graph = build_graph(data)
  File "C:\Users\ABDUL REHMAN\AppData\Local\Programs\Python\Python310\lib\site-packages\langflow\interface\run.py", line 49, in build_graph
    return Graph(nodes, edges)
  File "C:\Users\ABDUL REHMAN\AppData\Local\Programs\Python\Python310\lib\site-packages\langflow\graph\graph.py", line 43, in __init__
    self._build_graph()
  File "C:\Users\ABDUL REHMAN\AppData\Local\Programs\Python\Python310\lib\site-packages\langflow\graph\graph.py", line 56, in _build_graph
    node._build_params()
  File "C:\Users\ABDUL REHMAN\AppData\Local\Programs\Python\Python310\lib\site-packages\langflow\graph\base.py", line 94, in _build_params
    file_path = cache_utils.save_binary_file(
  File "C:\Users\ABDUL REHMAN\AppData\Local\Programs\Python\Python310\lib\site-packages\langflow\cache\base.py", line 25, in wrapper
    return func(*args, **kwargs)
  File "C:\Users\ABDUL REHMAN\AppData\Local\Programs\Python\Python310\lib\site-packages\langflow\cache\base.py", line 118, in save_binary_file
    raise ValueError(f"File {file_name} is not accepted")
ValueError: File  is not accepted
2023-05-05 19:27:27,132 - ERROR - File  is not accepted
Traceback (most recent call last):
  File "C:\Users\ABDUL REHMAN\AppData\Local\Programs\Python\Python310\lib\site-packages\langflow\api\validate.py", line 44, in post_validate_node
    graph = build_graph(data)
  File "C:\Users\ABDUL REHMAN\AppData\Local\Programs\Python\Python310\lib\site-packages\langflow\interface\run.py", line 49, in build_graph
    return Graph(nodes, edges)
  File "C:\Users\ABDUL REHMAN\AppData\Local\Programs\Python\Python310\lib\site-packages\langflow\graph\graph.py", line 43, in __init__
    self._build_graph()
  File "C:\Users\ABDUL REHMAN\AppData\Local\Programs\Python\Python310\lib\site-packages\langflow\graph\graph.py", line 56, in _build_graph
    node._build_params()
  File "C:\Users\ABDUL REHMAN\AppData\Local\Programs\Python\Python310\lib\site-packages\langflow\graph\base.py", line 94, in _build_params
    file_path = cache_utils.save_binary_file(
  File "C:\Users\ABDUL REHMAN\AppData\Local\Programs\Python\Python310\lib\site-packages\langflow\cache\base.py", line 25, in wrapper
    return func(*args, **kwargs)
  File "C:\Users\ABDUL REHMAN\AppData\Local\Programs\Python\Python310\lib\site-packages\langflow\cache\base.py", line 118, in save_binary_file
    raise ValueError(f"File {file_name} is not accepted")
ValueError: File  is not accepted
2023-05-05 19:27:27,342 - ERROR - File  is not accepted
Traceback (most recent call last):
  File "C:\Users\ABDUL REHMAN\AppData\Local\Programs\Python\Python310\lib\site-packages\langflow\api\validate.py", line 44, in post_validate_node
    graph = build_graph(data)
  File "C:\Users\ABDUL REHMAN\AppData\Local\Programs\Python\Python310\lib\site-packages\langflow\interface\run.py", line 49, in build_graph
    return Graph(nodes, edges)
  File "C:\Users\ABDUL REHMAN\AppData\Local\Programs\Python\Python310\lib\site-packages\langflow\graph\graph.py", line 43, in __init__
    self._build_graph()
  File "C:\Users\ABDUL REHMAN\AppData\Local\Programs\Python\Python310\lib\site-packages\langflow\graph\graph.py", line 56, in _build_graph
    node._build_params()
  File "C:\Users\ABDUL REHMAN\AppData\Local\Programs\Python\Python310\lib\site-packages\langflow\graph\base.py", line 94, in _build_params
    file_path = cache_utils.save_binary_file(
  File "C:\Users\ABDUL REHMAN\AppData\Local\Programs\Python\Python310\lib\site-packages\langflow\cache\base.py", line 25, in wrapper
    return func(*args, **kwargs)
  File "C:\Users\ABDUL REHMAN\AppData\Local\Programs\Python\Python310\lib\site-packages\langflow\cache\base.py", line 118, in save_binary_file
    raise ValueError(f"File {file_name} is not accepted")
ValueError: File  is not accepted
2023-05-05 19:27:27,506 - ERROR - File  is not accepted
Traceback (most recent call last):
  File "C:\Users\ABDUL REHMAN\AppData\Local\Programs\Python\Python310\lib\site-packages\langflow\api\validate.py", line 44, in post_validate_node
    graph = build_graph(data)
  File "C:\Users\ABDUL REHMAN\AppData\Local\Programs\Python\Python310\lib\site-packages\langflow\interface\run.py", line 49, in build_graph
    return Graph(nodes, edges)
  File "C:\Users\ABDUL REHMAN\AppData\Local\Programs\Python\Python310\lib\site-packages\langflow\graph\graph.py", line 43, in __init__
    self._build_graph()
  File "C:\Users\ABDUL REHMAN\AppData\Local\Programs\Python\Python310\lib\site-packages\langflow\graph\graph.py", line 56, in _build_graph
    node._build_params()
  File "C:\Users\ABDUL REHMAN\AppData\Local\Programs\Python\Python310\lib\site-packages\langflow\graph\base.py", line 94, in _build_params
    file_path = cache_utils.save_binary_file(
  File "C:\Users\ABDUL REHMAN\AppData\Local\Programs\Python\Python310\lib\site-packages\langflow\cache\base.py", line 25, in wrapper
    return func(*args, **kwargs)
  File "C:\Users\ABDUL REHMAN\AppData\Local\Programs\Python\Python310\lib\site-packages\langflow\cache\base.py", line 118, in save_binary_file
    raise ValueError(f"File {file_name} is not accepted")
ValueError: File  is not accepted
2023-05-05 19:27:27,727 - ERROR - File  is not accepted
Traceback (most recent call last):
  File "C:\Users\ABDUL REHMAN\AppData\Local\Programs\Python\Python310\lib\site-packages\langflow\api\validate.py", line 44, in post_validate_node
    graph = build_graph(data)
  File "C:\Users\ABDUL REHMAN\AppData\Local\Programs\Python\Python310\lib\site-packages\langflow\interface\run.py", line 49, in build_graph
    return Graph(nodes, edges)
  File "C:\Users\ABDUL REHMAN\AppData\Local\Programs\Python\Python310\lib\site-packages\langflow\graph\graph.py", line 43, in __init__
    self._build_graph()
  File "C:\Users\ABDUL REHMAN\AppData\Local\Programs\Python\Python310\lib\site-packages\langflow\graph\graph.py", line 56, in _build_graph
    node._build_params()
  File "C:\Users\ABDUL REHMAN\AppData\Local\Programs\Python\Python310\lib\site-packages\langflow\graph\base.py", line 94, in _build_params
    file_path = cache_utils.save_binary_file(
  File "C:\Users\ABDUL REHMAN\AppData\Local\Programs\Python\Python310\lib\site-packages\langflow\cache\base.py", line 25, in wrapper
    return func(*args, **kwargs)
  File "C:\Users\ABDUL REHMAN\AppData\Local\Programs\Python\Python310\lib\site-packages\langflow\cache\base.py", line 118, in save_binary_file
    raise ValueError(f"File {file_name} is not accepted")
ValueError: File  is not accepted
2023-05-05 19:27:27,900 - ERROR - File  is not accepted
Traceback (most recent call last):
  File "C:\Users\ABDUL REHMAN\AppData\Local\Programs\Python\Python310\lib\site-packages\langflow\api\validate.py", line 44, in post_validate_node
    graph = build_graph(data)
  File "C:\Users\ABDUL REHMAN\AppData\Local\Programs\Python\Python310\lib\site-packages\langflow\interface\run.py", line 49, in build_graph
    return Graph(nodes, edges)
  File "C:\Users\ABDUL REHMAN\AppData\Local\Programs\Python\Python310\lib\site-packages\langflow\graph\graph.py", line 43, in __init__
    self._build_graph()
  File "C:\Users\ABDUL REHMAN\AppData\Local\Programs\Python\Python310\lib\site-packages\langflow\graph\graph.py", line 56, in _build_graph
    node._build_params()
  File "C:\Users\ABDUL REHMAN\AppData\Local\Programs\Python\Python310\lib\site-packages\langflow\graph\base.py", line 94, in _build_params
    file_path = cache_utils.save_binary_file(
  File "C:\Users\ABDUL REHMAN\AppData\Local\Programs\Python\Python310\lib\site-packages\langflow\cache\base.py", line 25, in wrapper
    return func(*args, **kwargs)
  File "C:\Users\ABDUL REHMAN\AppData\Local\Programs\Python\Python310\lib\site-packages\langflow\cache\base.py", line 118, in save_binary_file
    raise ValueError(f"File {file_name} is not accepted")
ValueError: File  is not accepted
2023-05-05 19:27:28,064 - ERROR - File  is not accepted
Traceback (most recent call last):
  File "C:\Users\ABDUL REHMAN\AppData\Local\Programs\Python\Python310\lib\site-packages\langflow\api\validate.py", line 44, in post_validate_node
    graph = build_graph(data)
  File "C:\Users\ABDUL REHMAN\AppData\Local\Programs\Python\Python310\lib\site-packages\langflow\interface\run.py", line 49, in build_graph
    return Graph(nodes, edges)
  File "C:\Users\ABDUL REHMAN\AppData\Local\Programs\Python\Python310\lib\site-packages\langflow\graph\graph.py", line 43, in __init__
    self._build_graph()
  File "C:\Users\ABDUL REHMAN\AppData\Local\Programs\Python\Python310\lib\site-packages\langflow\graph\graph.py", line 56, in _build_graph
    node._build_params()
  File "C:\Users\ABDUL REHMAN\AppData\Local\Programs\Python\Python310\lib\site-packages\langflow\graph\base.py", line 94, in _build_params
    file_path = cache_utils.save_binary_file(
  File "C:\Users\ABDUL REHMAN\AppData\Local\Programs\Python\Python310\lib\site-packages\langflow\cache\base.py", line 25, in wrapper
    return func(*args, **kwargs)
  File "C:\Users\ABDUL REHMAN\AppData\Local\Programs\Python\Python310\lib\site-packages\langflow\cache\base.py", line 118, in save_binary_file
    raise ValueError(f"File {file_name} is not accepted")
ValueError: File  is not accepted
2023-05-05 19:27:28,241 - ERROR - File  is not accepted
Traceback (most recent call last):
  File "C:\Users\ABDUL REHMAN\AppData\Local\Programs\Python\Python310\lib\site-packages\langflow\api\validate.py", line 44, in post_validate_node
    graph = build_graph(data)
  File "C:\Users\ABDUL REHMAN\AppData\Local\Programs\Python\Python310\lib\site-packages\langflow\interface\run.py", line 49, in build_graph
    return Graph(nodes, edges)
  File "C:\Users\ABDUL REHMAN\AppData\Local\Programs\Python\Python310\lib\site-packages\langflow\graph\graph.py", line 43, in __init__
    self._build_graph()
  File "C:\Users\ABDUL REHMAN\AppData\Local\Programs\Python\Python310\lib\site-packages\langflow\graph\graph.py", line 56, in _build_graph
    node._build_params()
  File "C:\Users\ABDUL REHMAN\AppData\Local\Programs\Python\Python310\lib\site-packages\langflow\graph\base.py", line 94, in _build_params
    file_path = cache_utils.save_binary_file(
  File "C:\Users\ABDUL REHMAN\AppData\Local\Programs\Python\Python310\lib\site-packages\langflow\cache\base.py", line 25, in wrapper
    return func(*args, **kwargs)
  File "C:\Users\ABDUL REHMAN\AppData\Local\Programs\Python\Python310\lib\site-packages\langflow\cache\base.py", line 118, in save_binary_file
    raise ValueError(f"File {file_name} is not accepted")
ValueError: File  is not accepted
2023-05-05 19:27:28,521 - ERROR - File  is not accepted
Traceback (most recent call last):
  File "C:\Users\ABDUL REHMAN\AppData\Local\Programs\Python\Python310\lib\site-packages\langflow\api\validate.py", line 44, in post_validate_node
    graph = build_graph(data)
  File "C:\Users\ABDUL REHMAN\AppData\Local\Programs\Python\Python310\lib\site-packages\langflow\interface\run.py", line 49, in build_graph
    return Graph(nodes, edges)
  File "C:\Users\ABDUL REHMAN\AppData\Local\Programs\Python\Python310\lib\site-packages\langflow\graph\graph.py", line 43, in __init__
    self._build_graph()
  File "C:\Users\ABDUL REHMAN\AppData\Local\Programs\Python\Python310\lib\site-packages\langflow\graph\graph.py", line 56, in _build_graph
    node._build_params()
  File "C:\Users\ABDUL REHMAN\AppData\Local\Programs\Python\Python310\lib\site-packages\langflow\graph\base.py", line 94, in _build_params
    file_path = cache_utils.save_binary_file(
  File "C:\Users\ABDUL REHMAN\AppData\Local\Programs\Python\Python310\lib\site-packages\langflow\cache\base.py", line 25, in wrapper
    return func(*args, **kwargs)
  File "C:\Users\ABDUL REHMAN\AppData\Local\Programs\Python\Python310\lib\site-packages\langflow\cache\base.py", line 118, in save_binary_file
    raise ValueError(f"File {file_name} is not accepted")
ValueError: File  is not accepted
2023-05-05 19:27:28,627 - ERROR - File  is not accepted
Traceback (most recent call last):
  File "C:\Users\ABDUL REHMAN\AppData\Local\Programs\Python\Python310\lib\site-packages\langflow\api\validate.py", line 44, in post_validate_node
    graph = build_graph(data)
  File "C:\Users\ABDUL REHMAN\AppData\Local\Programs\Python\Python310\lib\site-packages\langflow\interface\run.py", line 49, in build_graph
    return Graph(nodes, edges)
  File "C:\Users\ABDUL REHMAN\AppData\Local\Programs\Python\Python310\lib\site-packages\langflow\graph\graph.py", line 43, in __init__
    self._build_graph()
  File "C:\Users\ABDUL REHMAN\AppData\Local\Programs\Python\Python310\lib\site-packages\langflow\graph\graph.py", line 56, in _build_graph
    node._build_params()
  File "C:\Users\ABDUL REHMAN\AppData\Local\Programs\Python\Python310\lib\site-packages\langflow\graph\base.py", line 94, in _build_params
    file_path = cache_utils.save_binary_file(
  File "C:\Users\ABDUL REHMAN\AppData\Local\Programs\Python\Python310\lib\site-packages\langflow\cache\base.py", line 25, in wrapper
    return func(*args, **kwargs)
  File "C:\Users\ABDUL REHMAN\AppData\Local\Programs\Python\Python310\lib\site-packages\langflow\cache\base.py", line 118, in save_binary_file
    raise ValueError(f"File {file_name} is not accepted")
ValueError: File  is not accepted
2023-05-05 19:27:28,748 - ERROR - File  is not accepted
Traceback (most recent call last):
  File "C:\Users\ABDUL REHMAN\AppData\Local\Programs\Python\Python310\lib\site-packages\langflow\api\validate.py", line 44, in post_validate_node
    graph = build_graph(data)
  File "C:\Users\ABDUL REHMAN\AppData\Local\Programs\Python\Python310\lib\site-packages\langflow\interface\run.py", line 49, in build_graph
    return Graph(nodes, edges)
  File "C:\Users\ABDUL REHMAN\AppData\Local\Programs\Python\Python310\lib\site-packages\langflow\graph\graph.py", line 43, in __init__
    self._build_graph()
  File "C:\Users\ABDUL REHMAN\AppData\Local\Programs\Python\Python310\lib\site-packages\langflow\graph\graph.py", line 56, in _build_graph
    node._build_params()
  File "C:\Users\ABDUL REHMAN\AppData\Local\Programs\Python\Python310\lib\site-packages\langflow\graph\base.py", line 94, in _build_params
    file_path = cache_utils.save_binary_file(
  File "C:\Users\ABDUL REHMAN\AppData\Local\Programs\Python\Python310\lib\site-packages\langflow\cache\base.py", line 25, in wrapper
    return func(*args, **kwargs)
  File "C:\Users\ABDUL REHMAN\AppData\Local\Programs\Python\Python310\lib\site-packages\langflow\cache\base.py", line 118, in save_binary_file
    raise ValueError(f"File {file_name} is not accepted")
ValueError: File  is not accepted
2023-05-05 19:41:07,741 - ERROR - File  is not accepted
Traceback (most recent call last):
  File "C:\Users\ABDUL REHMAN\AppData\Local\Programs\Python\Python310\lib\site-packages\langflow\api\validate.py", line 44, in post_validate_node
    graph = build_graph(data)
  File "C:\Users\ABDUL REHMAN\AppData\Local\Programs\Python\Python310\lib\site-packages\langflow\interface\run.py", line 49, in build_graph
    return Graph(nodes, edges)
  File "C:\Users\ABDUL REHMAN\AppData\Local\Programs\Python\Python310\lib\site-packages\langflow\graph\graph.py", line 43, in __init__
    self._build_graph()
  File "C:\Users\ABDUL REHMAN\AppData\Local\Programs\Python\Python310\lib\site-packages\langflow\graph\graph.py", line 56, in _build_graph
    node._build_params()
  File "C:\Users\ABDUL REHMAN\AppData\Local\Programs\Python\Python310\lib\site-packages\langflow\graph\base.py", line 94, in _build_params
    file_path = cache_utils.save_binary_file(
  File "C:\Users\ABDUL REHMAN\AppData\Local\Programs\Python\Python310\lib\site-packages\langflow\cache\base.py", line 25, in wrapper
    return func(*args, **kwargs)
  File "C:\Users\ABDUL REHMAN\AppData\Local\Programs\Python\Python310\lib\site-packages\langflow\cache\base.py", line 118, in save_binary_file
    raise ValueError(f"File {file_name} is not accepted")
ValueError: File  is not accepted
2023-05-05 19:41:09,768 - ERROR - File  is not accepted
Traceback (most recent call last):
  File "C:\Users\ABDUL REHMAN\AppData\Local\Programs\Python\Python310\lib\site-packages\langflow\api\validate.py", line 44, in post_validate_node
    graph = build_graph(data)
  File "C:\Users\ABDUL REHMAN\AppData\Local\Programs\Python\Python310\lib\site-packages\langflow\interface\run.py", line 49, in build_graph
    return Graph(nodes, edges)
  File "C:\Users\ABDUL REHMAN\AppData\Local\Programs\Python\Python310\lib\site-packages\langflow\graph\graph.py", line 43, in __init__
    self._build_graph()
  File "C:\Users\ABDUL REHMAN\AppData\Local\Programs\Python\Python310\lib\site-packages\langflow\graph\graph.py", line 56, in _build_graph
    node._build_params()
  File "C:\Users\ABDUL REHMAN\AppData\Local\Programs\Python\Python310\lib\site-packages\langflow\graph\base.py", line 94, in _build_params
    file_path = cache_utils.save_binary_file(
  File "C:\Users\ABDUL REHMAN\AppData\Local\Programs\Python\Python310\lib\site-packages\langflow\cache\base.py", line 25, in wrapper
    return func(*args, **kwargs)
  File "C:\Users\ABDUL REHMAN\AppData\Local\Programs\Python\Python310\lib\site-packages\langflow\cache\base.py", line 118, in save_binary_file
    raise ValueError(f"File {file_name} is not accepted")
ValueError: File  is not accepted
2023-05-05 19:41:12,242 - ERROR - File  is not accepted
Traceback (most recent call last):
  File "C:\Users\ABDUL REHMAN\AppData\Local\Programs\Python\Python310\lib\site-packages\langflow\api\validate.py", line 44, in post_validate_node
    graph = build_graph(data)
  File "C:\Users\ABDUL REHMAN\AppData\Local\Programs\Python\Python310\lib\site-packages\langflow\interface\run.py", line 49, in build_graph
    return Graph(nodes, edges)
  File "C:\Users\ABDUL REHMAN\AppData\Local\Programs\Python\Python310\lib\site-packages\langflow\graph\graph.py", line 43, in __init__
    self._build_graph()
  File "C:\Users\ABDUL REHMAN\AppData\Local\Programs\Python\Python310\lib\site-packages\langflow\graph\graph.py", line 56, in _build_graph
    node._build_params()
  File "C:\Users\ABDUL REHMAN\AppData\Local\Programs\Python\Python310\lib\site-packages\langflow\graph\base.py", line 94, in _build_params
    file_path = cache_utils.save_binary_file(
  File "C:\Users\ABDUL REHMAN\AppData\Local\Programs\Python\Python310\lib\site-packages\langflow\cache\base.py", line 25, in wrapper
    return func(*args, **kwargs)
  File "C:\Users\ABDUL REHMAN\AppData\Local\Programs\Python\Python310\lib\site-packages\langflow\cache\base.py", line 118, in save_binary_file
    raise ValueError(f"File {file_name} is not accepted")
ValueError: File  is not accepted
2023-05-05 19:41:15,742 - ERROR - File  is not accepted
Traceback (most recent call last):
  File "C:\Users\ABDUL REHMAN\AppData\Local\Programs\Python\Python310\lib\site-packages\langflow\api\validate.py", line 44, in post_validate_node
    graph = build_graph(data)
  File "C:\Users\ABDUL REHMAN\AppData\Local\Programs\Python\Python310\lib\site-packages\langflow\interface\run.py", line 49, in build_graph
    return Graph(nodes, edges)
  File "C:\Users\ABDUL REHMAN\AppData\Local\Programs\Python\Python310\lib\site-packages\langflow\graph\graph.py", line 43, in __init__
    self._build_graph()
  File "C:\Users\ABDUL REHMAN\AppData\Local\Programs\Python\Python310\lib\site-packages\langflow\graph\graph.py", line 56, in _build_graph
    node._build_params()
  File "C:\Users\ABDUL REHMAN\AppData\Local\Programs\Python\Python310\lib\site-packages\langflow\graph\base.py", line 94, in _build_params
    file_path = cache_utils.save_binary_file(
  File "C:\Users\ABDUL REHMAN\AppData\Local\Programs\Python\Python310\lib\site-packages\langflow\cache\base.py", line 25, in wrapper
    return func(*args, **kwargs)
  File "C:\Users\ABDUL REHMAN\AppData\Local\Programs\Python\Python310\lib\site-packages\langflow\cache\base.py", line 118, in save_binary_file
    raise ValueError(f"File {file_name} is not accepted")
ValueError: File  is not accepted
2023-05-05 19:41:16,058 - ERROR - File  is not accepted
Traceback (most recent call last):
  File "C:\Users\ABDUL REHMAN\AppData\Local\Programs\Python\Python310\lib\site-packages\langflow\api\validate.py", line 44, in post_validate_node
    graph = build_graph(data)
  File "C:\Users\ABDUL REHMAN\AppData\Local\Programs\Python\Python310\lib\site-packages\langflow\interface\run.py", line 49, in build_graph
    return Graph(nodes, edges)
  File "C:\Users\ABDUL REHMAN\AppData\Local\Programs\Python\Python310\lib\site-packages\langflow\graph\graph.py", line 43, in __init__
    self._build_graph()
  File "C:\Users\ABDUL REHMAN\AppData\Local\Programs\Python\Python310\lib\site-packages\langflow\graph\graph.py", line 56, in _build_graph
    node._build_params()
  File "C:\Users\ABDUL REHMAN\AppData\Local\Programs\Python\Python310\lib\site-packages\langflow\graph\base.py", line 94, in _build_params
    file_path = cache_utils.save_binary_file(
  File "C:\Users\ABDUL REHMAN\AppData\Local\Programs\Python\Python310\lib\site-packages\langflow\cache\base.py", line 25, in wrapper
    return func(*args, **kwargs)
  File "C:\Users\ABDUL REHMAN\AppData\Local\Programs\Python\Python310\lib\site-packages\langflow\cache\base.py", line 118, in save_binary_file
    raise ValueError(f"File {file_name} is not accepted")
ValueError: File  is not accepted
2023-05-05 19:41:27,226 - ERROR - File  is not accepted
Traceback (most recent call last):
  File "C:\Users\ABDUL REHMAN\AppData\Local\Programs\Python\Python310\lib\site-packages\langflow\api\validate.py", line 44, in post_validate_node
    graph = build_graph(data)
  File "C:\Users\ABDUL REHMAN\AppData\Local\Programs\Python\Python310\lib\site-packages\langflow\interface\run.py", line 49, in build_graph
    return Graph(nodes, edges)
  File "C:\Users\ABDUL REHMAN\AppData\Local\Programs\Python\Python310\lib\site-packages\langflow\graph\graph.py", line 43, in __init__
    self._build_graph()
  File "C:\Users\ABDUL REHMAN\AppData\Local\Programs\Python\Python310\lib\site-packages\langflow\graph\graph.py", line 56, in _build_graph
    node._build_params()
  File "C:\Users\ABDUL REHMAN\AppData\Local\Programs\Python\Python310\lib\site-packages\langflow\graph\base.py", line 94, in _build_params
    file_path = cache_utils.save_binary_file(
  File "C:\Users\ABDUL REHMAN\AppData\Local\Programs\Python\Python310\lib\site-packages\langflow\cache\base.py", line 25, in wrapper
    return func(*args, **kwargs)
  File "C:\Users\ABDUL REHMAN\AppData\Local\Programs\Python\Python310\lib\site-packages\langflow\cache\base.py", line 118, in save_binary_file
    raise ValueError(f"File {file_name} is not accepted")
ValueError: File  is not accepted
2023-05-05 19:41:27,352 - ERROR - File  is not accepted
Traceback (most recent call last):
  File "C:\Users\ABDUL REHMAN\AppData\Local\Programs\Python\Python310\lib\site-packages\langflow\api\validate.py", line 44, in post_validate_node
    graph = build_graph(data)
  File "C:\Users\ABDUL REHMAN\AppData\Local\Programs\Python\Python310\lib\site-packages\langflow\interface\run.py", line 49, in build_graph
    return Graph(nodes, edges)
  File "C:\Users\ABDUL REHMAN\AppData\Local\Programs\Python\Python310\lib\site-packages\langflow\graph\graph.py", line 43, in __init__
    self._build_graph()
  File "C:\Users\ABDUL REHMAN\AppData\Local\Programs\Python\Python310\lib\site-packages\langflow\graph\graph.py", line 56, in _build_graph
    node._build_params()
  File "C:\Users\ABDUL REHMAN\AppData\Local\Programs\Python\Python310\lib\site-packages\langflow\graph\base.py", line 94, in _build_params
    file_path = cache_utils.save_binary_file(
  File "C:\Users\ABDUL REHMAN\AppData\Local\Programs\Python\Python310\lib\site-packages\langflow\cache\base.py", line 25, in wrapper
    return func(*args, **kwargs)
  File "C:\Users\ABDUL REHMAN\AppData\Local\Programs\Python\Python310\lib\site-packages\langflow\cache\base.py", line 118, in save_binary_file
    raise ValueError(f"File {file_name} is not accepted")
ValueError: File  is not accepted
2023-05-05 19:41:27,358 - ERROR - File  is not accepted
Traceback (most recent call last):
  File "C:\Users\ABDUL REHMAN\AppData\Local\Programs\Python\Python310\lib\site-packages\langflow\api\validate.py", line 44, in post_validate_node
    graph = build_graph(data)
  File "C:\Users\ABDUL REHMAN\AppData\Local\Programs\Python\Python310\lib\site-packages\langflow\interface\run.py", line 49, in build_graph
    return Graph(nodes, edges)
  File "C:\Users\ABDUL REHMAN\AppData\Local\Programs\Python\Python310\lib\site-packages\langflow\graph\graph.py", line 43, in __init__
    self._build_graph()
  File "C:\Users\ABDUL REHMAN\AppData\Local\Programs\Python\Python310\lib\site-packages\langflow\graph\graph.py", line 56, in _build_graph
    node._build_params()
  File "C:\Users\ABDUL REHMAN\AppData\Local\Programs\Python\Python310\lib\site-packages\langflow\graph\base.py", line 94, in _build_params
    file_path = cache_utils.save_binary_file(
  File "C:\Users\ABDUL REHMAN\AppData\Local\Programs\Python\Python310\lib\site-packages\langflow\cache\base.py", line 25, in wrapper
    return func(*args, **kwargs)
  File "C:\Users\ABDUL REHMAN\AppData\Local\Programs\Python\Python310\lib\site-packages\langflow\cache\base.py", line 118, in save_binary_file
    raise ValueError(f"File {file_name} is not accepted")
ValueError: File  is not accepted
2023-05-05 19:41:30,180 - ERROR - File  is not accepted
Traceback (most recent call last):
  File "C:\Users\ABDUL REHMAN\AppData\Local\Programs\Python\Python310\lib\site-packages\langflow\api\validate.py", line 44, in post_validate_node
    graph = build_graph(data)
  File "C:\Users\ABDUL REHMAN\AppData\Local\Programs\Python\Python310\lib\site-packages\langflow\interface\run.py", line 49, in build_graph
    return Graph(nodes, edges)
  File "C:\Users\ABDUL REHMAN\AppData\Local\Programs\Python\Python310\lib\site-packages\langflow\graph\graph.py", line 43, in __init__
    self._build_graph()
  File "C:\Users\ABDUL REHMAN\AppData\Local\Programs\Python\Python310\lib\site-packages\langflow\graph\graph.py", line 56, in _build_graph
    node._build_params()
  File "C:\Users\ABDUL REHMAN\AppData\Local\Programs\Python\Python310\lib\site-packages\langflow\graph\base.py", line 94, in _build_params
    file_path = cache_utils.save_binary_file(
  File "C:\Users\ABDUL REHMAN\AppData\Local\Programs\Python\Python310\lib\site-packages\langflow\cache\base.py", line 25, in wrapper
    return func(*args, **kwargs)
  File "C:\Users\ABDUL REHMAN\AppData\Local\Programs\Python\Python310\lib\site-packages\langflow\cache\base.py", line 118, in save_binary_file
    raise ValueError(f"File {file_name} is not accepted")
ValueError: File  is not accepted
2023-05-05 19:41:30,511 - ERROR - File  is not accepted
Traceback (most recent call last):
  File "C:\Users\ABDUL REHMAN\AppData\Local\Programs\Python\Python310\lib\site-packages\langflow\api\validate.py", line 44, in post_validate_node
    graph = build_graph(data)
  File "C:\Users\ABDUL REHMAN\AppData\Local\Programs\Python\Python310\lib\site-packages\langflow\interface\run.py", line 49, in build_graph
    return Graph(nodes, edges)
  File "C:\Users\ABDUL REHMAN\AppData\Local\Programs\Python\Python310\lib\site-packages\langflow\graph\graph.py", line 43, in __init__
    self._build_graph()
  File "C:\Users\ABDUL REHMAN\AppData\Local\Programs\Python\Python310\lib\site-packages\langflow\graph\graph.py", line 56, in _build_graph
    node._build_params()
  File "C:\Users\ABDUL REHMAN\AppData\Local\Programs\Python\Python310\lib\site-packages\langflow\graph\base.py", line 94, in _build_params
    file_path = cache_utils.save_binary_file(
  File "C:\Users\ABDUL REHMAN\AppData\Local\Programs\Python\Python310\lib\site-packages\langflow\cache\base.py", line 25, in wrapper
    return func(*args, **kwargs)
  File "C:\Users\ABDUL REHMAN\AppData\Local\Programs\Python\Python310\lib\site-packages\langflow\cache\base.py", line 118, in save_binary_file
    raise ValueError(f"File {file_name} is not accepted")
ValueError: File  is not accepted
2023-05-05 19:41:30,511 - ERROR - File  is not accepted
Traceback (most recent call last):
  File "C:\Users\ABDUL REHMAN\AppData\Local\Programs\Python\Python310\lib\site-packages\langflow\api\validate.py", line 44, in post_validate_node
    graph = build_graph(data)
  File "C:\Users\ABDUL REHMAN\AppData\Local\Programs\Python\Python310\lib\site-packages\langflow\interface\run.py", line 49, in build_graph
    return Graph(nodes, edges)
  File "C:\Users\ABDUL REHMAN\AppData\Local\Programs\Python\Python310\lib\site-packages\langflow\graph\graph.py", line 43, in __init__
    self._build_graph()
  File "C:\Users\ABDUL REHMAN\AppData\Local\Programs\Python\Python310\lib\site-packages\langflow\graph\graph.py", line 56, in _build_graph
    node._build_params()
  File "C:\Users\ABDUL REHMAN\AppData\Local\Programs\Python\Python310\lib\site-packages\langflow\graph\base.py", line 94, in _build_params
    file_path = cache_utils.save_binary_file(
  File "C:\Users\ABDUL REHMAN\AppData\Local\Programs\Python\Python310\lib\site-packages\langflow\cache\base.py", line 25, in wrapper
    return func(*args, **kwargs)
  File "C:\Users\ABDUL REHMAN\AppData\Local\Programs\Python\Python310\lib\site-packages\langflow\cache\base.py", line 118, in save_binary_file
    raise ValueError(f"File {file_name} is not accepted")
ValueError: File  is not accepted
2023-05-05 19:44:12,121 - ERROR - 1001
Traceback (most recent call last):
  File "C:\Users\ABDUL REHMAN\AppData\Local\Programs\Python\Python310\lib\site-packages\langflow\api\chat_manager.py", line 161, in handle_websocket
    json_payload = await websocket.receive_json()
  File "C:\Users\ABDUL REHMAN\AppData\Local\Programs\Python\Python310\lib\site-packages\starlette\websockets.py", line 133, in receive_json
    self._raise_on_disconnect(message)
  File "C:\Users\ABDUL REHMAN\AppData\Local\Programs\Python\Python310\lib\site-packages\starlette\websockets.py", line 105, in _raise_on_disconnect
    raise WebSocketDisconnect(message["code"])
starlette.websockets.WebSocketDisconnect: 1001
2023-05-05 19:44:12,339 - ERROR - Unexpected ASGI message 'websocket.close', after sending 'websocket.close'.
Traceback (most recent call last):
  File "C:\Users\ABDUL REHMAN\AppData\Local\Programs\Python\Python310\lib\site-packages\langflow\api\chat_manager.py", line 161, in handle_websocket
    json_payload = await websocket.receive_json()
  File "C:\Users\ABDUL REHMAN\AppData\Local\Programs\Python\Python310\lib\site-packages\starlette\websockets.py", line 133, in receive_json
    self._raise_on_disconnect(message)
  File "C:\Users\ABDUL REHMAN\AppData\Local\Programs\Python\Python310\lib\site-packages\starlette\websockets.py", line 105, in _raise_on_disconnect
    raise WebSocketDisconnect(message["code"])
starlette.websockets.WebSocketDisconnect: 1001

During handling of the above exception, another exception occurred:

Traceback (most recent call last):
  File "C:\Users\ABDUL REHMAN\AppData\Local\Programs\Python\Python310\lib\site-packages\langflow\api\chat_manager.py", line 176, in handle_websocket
    await self.send_message(client_id, str(e))
  File "C:\Users\ABDUL REHMAN\AppData\Local\Programs\Python\Python310\lib\site-packages\langflow\api\chat_manager.py", line 96, in send_message
    await websocket.send_text(message)
  File "C:\Users\ABDUL REHMAN\AppData\Local\Programs\Python\Python310\lib\site-packages\starlette\websockets.py", line 163, in send_text
    await self.send({"type": "websocket.send", "text": data})
  File "C:\Users\ABDUL REHMAN\AppData\Local\Programs\Python\Python310\lib\site-packages\starlette\websockets.py", line 85, in send
    await self._send(message)
  File "C:\Users\ABDUL REHMAN\AppData\Local\Programs\Python\Python310\lib\site-packages\starlette\middleware\exceptions.py", line 65, in sender
    await send(message)
  File "C:\Users\ABDUL REHMAN\AppData\Local\Programs\Python\Python310\lib\site-packages\uvicorn\protocols\websockets\websockets_impl.py", line 329, in asgi_send
    raise RuntimeError(msg % message_type)
RuntimeError: Unexpected ASGI message 'websocket.send', after sending 'websocket.close'.

During handling of the above exception, another exception occurred:

Traceback (most recent call last):
  File "C:\Users\ABDUL REHMAN\AppData\Local\Programs\Python\Python310\lib\site-packages\langflow\api\chat.py", line 14, in websocket_endpoint
    await chat_manager.handle_websocket(client_id, websocket)
  File "C:\Users\ABDUL REHMAN\AppData\Local\Programs\Python\Python310\lib\site-packages\langflow\api\chat_manager.py", line 179, in handle_websocket
    await self.active_connections[client_id].close(
  File "C:\Users\ABDUL REHMAN\AppData\Local\Programs\Python\Python310\lib\site-packages\starlette\websockets.py", line 180, in close
    await self.send(
  File "C:\Users\ABDUL REHMAN\AppData\Local\Programs\Python\Python310\lib\site-packages\starlette\websockets.py", line 85, in send
    await self._send(message)
  File "C:\Users\ABDUL REHMAN\AppData\Local\Programs\Python\Python310\lib\site-packages\starlette\middleware\exceptions.py", line 65, in sender
    await send(message)
  File "C:\Users\ABDUL REHMAN\AppData\Local\Programs\Python\Python310\lib\site-packages\uvicorn\protocols\websockets\websockets_impl.py", line 329, in asgi_send
    raise RuntimeError(msg % message_type)
RuntimeError: Unexpected ASGI message 'websocket.close', after sending 'websocket.close'.
